Workbook

Sheet Overview of Everything
B2: Games | C2: Songs Released | D2: Total Songs | E2: Percentage Completion | G2: Special Thanks To:
B3: Rock Band 1 (Rewind Only) | C3: ='RB1'!C63 -> 27 | D3: ='RB1'!C64 -> 58 | E3: ='RB1'!C65 -> 0.46551724 | G3: Harmonix
B4: Rock Band 2 (Rewind Only) | C4: ='RB2'!C89 -> 34 | D4: ='RB2'!C90 -> 84 | E4: ='RB2'!C91 -> 0.4047619 | G4: =HYPERLINK("http://www.rockbandaide.com/","Rock Band Aide") -> Rock Band Aide
B5: Rock Band 3 (Rewind Only) | C5: ='RB3'!C88 -> 15 | D5: ='RB3'!C89 -> 83 | E5: ='RB3'!C90 -> 0.18072289 | G5: =HYPERLINK("http://rbdb.online/","rbdb.online") -> rbdb.online
B6: Lego Rock Band (Rewind Only) | C6: ='LEGO RB'!C50 -> 10 | D6: ='LEGO RB'!C51 -> 45 | E6: ='LEGO RB'!C52 -> 0.22222222 | G6: Whoever is that guy updating
B7: Rock Band Network (Rewind Only) | C7: =RBN!C1919 -> 194 | D7: =RBN!C1920 -> 1914 | E7: =RBN!C1921 -> 0.10135841 | G7: Rock Band DLC Wikipedia Page
B8: ~~~~~~~~~~~~~~~~~~~~~~~~~~~~~~~~~~~~~~~~~~
B9: Rock Band VR | C9: ='Rock Band VR'!C65 -> 53 | D9: ='Rock Band VR'!C66 -> 60 | E9: ='Rock Band VR'!C67 -> 0.88333333
B10: DLC | C10: ='Rock Band VR DLC'!C27 -> 22 | D10: ='Rock Band VR DLC'!C28 -> 22 | E10: ='Rock Band VR DLC'!C29 -> 1
B11: ~~~~~~~~~~~~~~~~~~~~~~~~~~~~~~~~~~~~~~~~~~
B12: Dropmix | C12: =Dropmix!C118 -> 44 | D12: =Dropmix!C119 -> 113 | E12: =Dropmix!C120 -> 0.38938053
B13: Fuser | C13: =Fuser!C93 -> 32 | D13: =Fuser!C94 -> 89 | E13: =Fuser!C95 -> 0.35955056 | G13: Made By:
B14: DLC | C14: ='Fuser DLC'!C144 -> 42 | D14: ='Fuser DLC'!C145 -> 139 | E14: ='Fuser DLC'!C146 -> 0.30215827 | G14: JMilla Potato
B15: ~~~~~~~~~~~~~~~~~~~~~~~~~~~~~~~~~~~~~~~~~~
B16: Guitar Hero | C16: ='GH1'!C52 -> 26 | D16: ='GH1'!C53 -> 47 | E16: ='GH1'!C54 -> 0.55319149
B17: Guitar Hero II | C17: ='GH2'!C79 -> 32 | D17: ='GH2'!C80 -> 74 | E17: ='GH2'!C81 -> 0.43243243
B18: DLC | C18: ='GH2 DLC'!C29 -> 11 | D18: ='GH2 DLC'!C30 -> 24 | E18: ='GH2 DLC'!C31 -> 0.45833333
B19: Guitar Hero III: Legends of Rock | C19: ='GH3'!C76 -> 42 | D19: ='GH3'!C77 -> 71 | E19: ='GH3'!C78 -> 0.5915493
B20: DLC | C20: ='GH3 DLC'!C70 -> 21 | D20: ='GH3 DLC'!C71 -> 65 | E20: ='GH3 DLC'!C72 -> 0.32307692
B21: Guitar Hero: World Tour | C21: ='GH World Tour'!C89 -> 54 | D21: ='GH World Tour'!C90 -> 84 | E21: ='GH World Tour'!C91 -> 0.64285714 | G21: My Links
B22: Guitar Hero 5 | C22: ='GH 5'!C90 -> 42 | D22: ='GH 5'!C91 -> 85 | E22: ='GH 5'!C92 -> 0.49411765 | G22: =HYPERLINK("https://www.youtube.com/channel/UC-1LzD9LF-Knd67UJBpG0rQ?view_as=public","YouTube") -> YouTube
B23: Guitar Hero: Warriors of Rock | C23: ='GH Warriors of Rock'!C92 -> 39 | D23: ='GH Warriors of Rock'!C93 -> 87 | E23: ='GH Warriors of Rock'!C94 -> 0.44827586 | G23: =HYPERLINK("https://twitter.com/JMilla_Potato?lang=en","Twitter") -> Twitter
B24: DLC | C24: ='Guitar Hero 456 DLC'!C399 -> 164 | D24: ='Guitar Hero 456 DLC'!C400 -> 394 | E24: ='Guitar Hero 456 DLC'!C401 -> 0.41624365
B25: ~~~~~~~~~~~~~~~~~~~~~~~~~~~~~~~~~~~~~~~~~~
B26: Guitar Hero: Live | C26: ='GH Live'!C47 -> 18 | D26: ='GH Live'!C48 -> 42 | E26: ='GH Live'!C49 -> 0.42857143 | G26: Let's Play Rock Band 4 Together!!
B27: Guitar Hero: TV | C27: ='GH TV'!C522 -> 171 | D27: ='GH TV'!C523 -> 517 | E27: ='GH TV'!C524 -> 0.33075435 | G27: XBox gt: ya AMERICA
B28: ~~~~~~~~~~~~~~~~~~~~~~~~~~~~~~~~~~~~~~~~~~
B29: Guitar Hero: Aerosmith | C29: ='GH Aerosmith'!C45 -> 17 | D29: ='GH Aerosmith'!C46 -> 40 | E29: ='GH Aerosmith'!C47 -> 0.425
B30: Guitar Hero: Metallica | C30: ='GH Metallica'!C57 -> 10 | D30: ='GH Metallica'!C58 -> 52 | E30: ='GH Metallica'!C59 -> 0.19230769
B31: Guitar Hero: Van Halen | C31: ='GH Van Halen'!C52 -> 21 | D31: ='GH Van Halen'!C53 -> 47 | E31: ='GH Van Halen'!C54 -> 0.44680851
B32: ~~~~~~~~~~~~~~~~~~~~~~~~~~~~~~~~~~~~~~~~~~
B33: Guitar Hero Encore: Rocks the 80s | C33: ='Rocks the 80s'!C35 -> 21 | D33: ='Rocks the 80s'!C36 -> 30 | E33: ='Rocks the 80s'!C37 -> 0.7
B34: Guitar Hero: Smash/Greatest Hits | C34: ='GH Smash Hits'!C53 -> 40 | D34: ='GH Smash Hits'!C54 -> 48 | E34: ='GH Smash Hits'!C55 -> 0.83333333
B35: Band Hero | C35: ='Band Hero'!C70 -> 33 | D35: ='Band Hero'!C71 -> 65 | E35: ='Band Hero'!C72 -> 0.50769231
B36: ~~~~~~~~~~~~~~~~~~~~~~~~~~~~~~~~~~~~~~~~~~
B37: Guitar Hero: On Tour | C37: ='Guitar Hero On Tour'!C36 -> 16 | D37: ='Guitar Hero On Tour'!C37 -> 31 | E37: ='Guitar Hero On Tour'!C38 -> 0.51612903
B38: Guitar Hero On Tour: Decades | C38: ='Guitar Hero On Tour Decades'!C40 -> 25 | D38: ='Guitar Hero On Tour Decades'!C41 -> 35 | E38: ='Guitar Hero On Tour Decades'!C42 -> 0.71428571
B39: Guitar Hero On Tour: Modern Hits | C39: ='Guitar Hero On Tour Modern Hits'!C45 -> 13 | D39: ='Guitar Hero On Tour Modern Hits'!C46 -> 40 | E39: ='Guitar Hero On Tour Modern Hits'!C47 -> 0.325
B40: Band Hero DS | C40: ='Band Hero DS'!C50 -> 25 | D40: ='Band Hero DS'!C51 -> 45 | E40: ='Band Hero DS'!C52 -> 0.55555556
B41: ~~~~~~~~~~~~~~~~~~~~~~~~~~~~~~~~~~~~~~~~~~
...

Sheet Spotlight Passes
D2: Season 2 | J2: Season 3 | P2: Season 4 Plus
B4: Week | C4: Song | D4: Artist | E4: Genre | F4: Year | H4: Week | I4: Song | J4: Artist | K4: Genre | L4: Year | N4: Week | O4: Song | P4: Artist | Q4: Genre | R4: Year
B5: 1 | C5: Stupid Girl | D5: Garbage | E5: Alternative | F5: 1995 | H5: 1 | I5: Johnny B. Goode | J5: Chuck Berry | K5: Classic Rock | L5: 1959 | N5: 1 | O5: 18 and Life | P5: Skid Row | Q5: Glam | R5: 1989
B6: 2 | C6: Stranglehold | D6: Ted Nugent | E6: Classic Rock | F6: 1975 | H6: 2 | I6: Play That Funky Music | J6: Wild Cherry | K6: R&B/Soul/Funk | L6: 1976 | N6: 2 | O6: Hooked On A Feeling | P6: Blue Suede | Q6: Classic Rock | R6: 1974
B7: 3 | C7: Ice Ice Baby | D7: Vanilla Ice | E7: Hip Hop/Rap | F7: 1990 | H7: 3 | I7: Blister In The Sun | J7: Violent Femmes | K7: Punk | L7: 1983 | N7: 3 | O7: Enjoy The Silence | P7: Depeche Mode | Q7: Pop/Dance/Electronic | R7: 1990
B8: 4 | C8: God Damn | D8: Avenged Sevenfold | E8: Metal | F8: 2016 | H8: 4 | I8: Karma Police | J8: Radiohead | K8: Alternative | L8: 1997 | N8: 4 | O8: I Remember You | P8: Skid Row | Q8: Glam | R8: 1989
B9: 5 | C9: Super Freak | D9: Rick James | E9: R&B/Soul/Funk | F9: 1981 | H9: 5 | I9: Save a Horse (Ride a Cowboy) | J9: Big & Rich | K9: Country | L9: 2004 | N9: 5 | O9: That Don't Impress Me Much | P9: Shania Twain | Q9: Country | R9: 1997
B10: 6 | C10: Burnin' for You | D10: Blue Oyster Cult | E10: Classic Rock | F10: 1981 | H10: 6 | I10: Twilght of the Thunder God | J10: Amon Amarth | K10: Metal | L10: 2008 | N10: 6 | O10: Lonely Is The Night | P10: Billy Squire | Q10: Classic Rock | R10: 1981
B11: 7 | C11: Heart of the Moment | D11: Asia | E11: Classic Rock | F11: 1982 | H11: 7 | I11: The Way You Used To Do | J11: Queens of the Stone Age | K11: Alternative | L11: 2017 | N11: 7 | O11: A Sky Full of Stars | P11: Coldplay | Q11: Alternative | R11: 2014
B12: 8 | C12: Down In a Hole | D12: Alice in Chains | E12: Grunge | F12: 1992 | H12: 8 | I12: Feel It Still | J12: Portugal. The Man | K12: Alternative | L12: 2017 | N12: 8 | O12: Absolutely (Story of a Girl) | P12: Nine Days | Q12: Alternative | R12: 2000
N13: 9 | O13: Unwell | P13: Matchbox Twenty | Q13: Alternative | R13: 2002
N14: 10 | O14: Broken | P14: Seether ft. Amy Lee | Q14: Rock | R14: 2004
D16: Season 5 | J16: Season 8 | P16: Season 9
B18: Week | C18: Song | D18: Artist | E18: Genre | F18: Year | H18: Week | I18: Song | J18: Artist | K18: Genre | L18: Year | N18: Week | O18: Song | P18: Artist | Q18: Genre | R18: Year
B19: 1 | C19: Unwritten | D19: Natasha Bedingfield | E19: Pop-Rock | F19: 2004 | H19: 1 | I19: Pictures of Girls | J19: Wallows | K19: Alternative | L19: 2018 | N19: 1 | O19: Girls Like You | P19: Maroon 5 | Q19: Pop-Rock | R19: 2017
B20: 2 | C20: Roll To Me | D20: Del Amitri | E20: Alternative | F20: 1995 | H20: 1 | I20: Simplify | J20: Young the Giant | K20: Alternative | L20: 2018 | N20: 2 | O20: Crazy On You | P20: Heart | Q20: Classic Rock | R20: 1976
B21: 3 | C21: Is She Really Going Out With Him | D21: Joe Jackson | E21: Classic Rock | F21: 1978 | H21: 2 | I21: HTML Rulez D00d | J21: The Devil Wears Prada | K21: Metal | L21: 2007 | N21: 3 | O21: Lose It | P21: Kane Brown | Q21: Country | R21: 2018
B22: 4 | C22: I Want You | D22: Savage Garden | E22: Pop-Rock | F22: 1997 | H22: 3 | I22: Unheavenly Creatures | J22: Coheed and Cambria | K22: Prog | L22: 2018 | N22: 3 | O22: Hotel Key | P22: Old Domination | Q22: Country | R22: 2018
B23: 5 | C23: Run-Around | D23: Blues Traveler | E23: Rock | F23: 1994 | H23: 3 | I23: When The Curtain Fall | J23: Greta Van Fleet | K23: Rock | L23: 2018 | N23: 4 | O23: Semi-Charmed Life '09 | P23: Third Eye Blind | Q23: Alternative | R23: 2009
B24: 6 | C24: Torn In Two | D24: Breaking Benjamin | E24: Rock | F24: 2018 | H24: 4 | I24: Business Time | J24: Flight of the Conchords | K24: Novelty | L24: 2008 | N24: 5 | O24: 99 | P24: Barns Country | Q24: Alternative | R24: 2018
B25: 7 | C25: Pictures of Matchstick Men | D25: Status Quo | E25: Classic Rock | F25: 1968 | H25: 5 | I25: Uncomfortable | J25: Halestorm | K25: Rock | L25: 2018 | N25: 5 | O25: Music Is Worth Living For | P25: Andrew W.K. | Q25: Rock | R25: 2018
B26: 8 | C26: Right Here, Right Now | D26: Jesus Jones | E26: Alternative | F26: 1990 | H26: 5 | I26: Graffiti | J26: CHVRCHES | K26: Alternative | L26: 2018 | N26: 6 | O26: Angel of Death | P26: Slayer | Q26: Metal | R26: 1986
H27: 6 | I27: Back to Me | J27: Of Mice & Men | K27: Metal | L27: 2018 | N27: 7 | O27: Starlight | P27: BABYMETAL | Q27: Metal | R27: 2018
H28: 7 | I28: Three Lives | J28: Octavision | K28: Prog | L28: 2016 | N28: 7 | O28: When Legends Rise | P28: Godsmack | Q28: Nu-Metal | R28: 2018
H29: 7 | I29: My Demons | J29: Starset | K29: Rock | L29: 2014 | N29: 8 | O29: Remedy | P29: Seether | Q29: Metal | R29: 2005
H30: 8 | I30: Little Black Backpack '09 | J30: Stroke 9 | K30: Rock | L30: 2010
D34: Season 10 | J34: Season 11 | P34: Season 12
B37: Week | C37: Song | D37: Artist | E37: Genre | F37: Year | H37: Week | I37: Song | J37: Artist | K37: Genre | L37: Year | N37: Week | O37: Song | P37: Artist | Q37: Genre | R37: Year
B38: 1 | C38: Shame | D38: Ellie King | E38: Alternative | F38: 2018 | H38: 1 | I38: I'm Gonna Be (500 Miles) | J38: The Proclaimers | K38: Rock | L38: 1988 | N38: 1 | O38: High Hopes | P38: Panic! At The Disco | Q38: Emo | R38: 2018
B39: 1 | C39: Body Talks | D39: The Struts | E39: Rock | F39: 2018 | H39: 2 | I39: Do Not Disturb | J39: Halestorm | K39: Rock | L39: 2018 | N39: 2 | O39: Change | P39: The Revivalists | Q39: Alternative | R39: 2018
B40: 2 | C40: The Triumph | D40: Jeff Williams ft. Casey Lee Williams | E40: Rock | F40: 2018 | H40: 3 | I40: Harmony Hall | J40: Vampire Weekend | K40: Indie Rock | L40: 2019 | N40: 3 | O40: 100 Days | P40: AJR | Q40: Pop-Rock | R40: 2019
B41: 3 | C41: The Reason | D41: Hoobastank | E41: Alternative | F41: 2004 | H41: 4 | I41: Longshot | J41: Catfish and the Bottlemen | K41: Indie Rock | L41: 2019 | N41: 4 | O41: Alligator | P41: Of Monsters and Men | Q41: Indie Rock | R41: 2019
B42: 4 | C42: Wagon Wheel | D42: Darius Rucker | E42: Country | F42: 2013 | H42: 5 | I42: Over My Head | J42: Judas & the Lion | K42: Alternative | L42: 2019 | N42: 5 | O42: Blame It On My Youth | P42: blink-182 | Q42: Punk | R42: 2019
B43: 5 | C43: Farewell, Mona Lisa | D43: The Dillinger Escape Plan | E43: Metal | F43: 2010 | H43: 6 | I43: Salvation | J43: The Strumbellas | K43: Alternative | L43: 2019 | N43: 6 | O43: Gloria | P43: The Lumineers | Q43: Indie Rock | R43: 2019
B44: 5 | C44: Bleed | D44: Meshuggah | E44: Metal | F44: 2008 | H44: 7 | I44: Tourniquet | J44: Breaking Benjamin | K44: Rock | L44: 2018 | N44: 7 | O44: Hurt | P44: Oliver Tree | Q44: Alternative | R44: 2019
B45: 6 | C45: MANTRA | D45: Bring Me The Horizon | E45: Nu-Metal | F45: 2019 | H45: 8 | I45: When Am I Going To Lose You? | J45: Local Natives | K45: Alternative | L45: 2019 | N45: 8 | O45: Missed Connections | P45: The Head and the Heart | Q45: Alternative | R45: 2019
B46: 7 | C46: Paradise | D46: Coldplay | E46: Alternative | F46: 2011 | H46: ??? | I46: ??? | J46: ??? | K46: ??? | L46: ???
B47: 8 | C47: When the Seasons Change | D47: Five Finger Death Punch | E47: Metal | F47: 2018
B48: 8 | C48: Superposition | D48: Young the Giant | E48: Alternative | F48: 2018
D52: Season 13 | J52: Apple Music Season | P52: Season 15
...

Sheet RB1
A1: 88
B2: Song | C2: Artist | D2: Release Date | E2: Source | F2: Notes
B3: Day Late, Dollar Short | C3: The Acro-Brats | D3: 42465 | E3: DLC | F3: Part of "30 Song Mega Pack"
B4: Train Kept A-Rollin' | C4: Aerosmith
B5: Blood Doll | C5: Anarchy Club | D5: 42465 | E5: DLC | F5: Part of "30 Song Mega Pack"
B6: Pleasure (Pleasure) | C6: Bang Camaro | D6: 42465 | E6: DLC | F6: Part of "30 Song Mega Pack"
B7: Sabotage | C7: Beastie Boys | D7: 44882 | E7: DLC | F7: Part of "Rock Band Rewind Pack 01" and "Rock Band 15th Anniversary"
B8: Paranoid | C8: Black Sabbath
B9: (Don't Fear) The Reaper | C9: Blue Öyster Cult | D9: 42754 | E9: DLC | F9: Part of "Solid '70s 01"
B10: Wanted Dead or Alive | C10: Bon Jovi | D10: 40491 | E10: DLC | F10: Part of "Bon Jovi Greatest Hits" Album
B11: Foreplay/Long Time | C11: Boston | D11: 44882 | E11: DLC | F11: Part of "Rock Band Rewind Pack 01" and "Rock Band 15th Anniversary"
B12: Should I Stay or Should I Go | C12: The Clash
B13: Welcome Home | C13: Coheed and Cambria | D13: 44735 | E13: DLC | F13: DLC Single
B14: Nightmare | C14: Crooked X
B15: Suffragette City | C15: David Bowie | D15: 43090 | E15: DLC | F15: DLC Single and part of "Rock Band Hits Pack"
B16: Can't Let Go | C16: Death of the Cool | D16: 42465 | E16: DLC | F16: Part of "30 Song Mega Pack"
B17: Highway Star | C17: Deep Purple
B18: Epic | C18: Faith No More
B19: Dead on Arrival | C19: Fall Out Boy | D19: 44882 | E19: DLC | F19: Part of "Rock Band Rewind Pack 01" and "Rock Band 15th Anniversary"
B20: I'm So Sick | C20: Flyleaf
B21: Learn to Fly | C21: Foo Fighters | D21: 43489 | E21: DLC | F21: DLC Single
B22: Brainpower | C22: Freezepop | D22: 42465 | E22: DLC | F22: Part of "30 Song Mega Pack"
B23: I Think I'm Paranoid | C23: Garbage
B24: Main Offender | C24: The Hives
B25: Celebrity Skin | C25: Hole
B26: I Get By | C26: Honest Bob and the Factory-to-Dealer Incentives | D26: 42465 | E26: DLC | F26: Part of "30 Song Mega Pack"
B27: Run to the Hills | C27: Iron Maiden | D27: 39973 | E27: DLC | F27: Part of "Iron Maiden Pack 01"
B28: Are You Gonna Be My Girl | C28: Jet | H28: Rock Band 1
B29: When You Were Young | C29: The Killers | D29: 43069 | E29: DLC | F29: DLC Single | H29: 39406
B30: Detroit Rock City | C30: Kiss
B31: 29 Fingers | C31: The Konks
B32: Enter Sandman | C32: Metallica
B33: Flirtin' with Disaster | C33: Molly Hatchet
B34: Time We Had | C34: The Mother Hips
B35: Mississippi Queen | C35: Mountain
B36: Electric Version | C36: The New Pornographers
B37: The Hand That Feeds | C37: Nine Inch Nails | D37: 43489 | E37: DLC | F37: DLC Single
B38: In Bloom | C38: Nirvana
B39: Here It Goes Again | C39: OK Go
B40: Green Grass and High Tides | C40: The Outlaws
...

Sheet Spotlight Rating
A1: Love | B1: 2
A2: 1 | B2: Shipwrecked | C2: Alestorm | D2: Metal | E2: 2011
A3: 7 | B3: Feed My Frankenstein | C3: Alice Cooper | D3: Rock | E3: 1991
A4: 6 | B4: No More Mr. Nice Guy | C4: Alice Cooper | D4: Rock | E4: 1973
A5: 3 | B5: Dear Maria, Count Me In | C5: All Time Low | D5: Emo | E5: 2007
A6: 6 | B6: Twilght of the Thunder God | C6: Amon Amarth | D6: Metal | E6: 2008
A7: 5 | B7: Music Is Worth Living For | C7: Andrew W.K. | D7: Rock | E7: 2018
A8: 8 | B8: Learn to Live | C8: Architects | D8: Metal | E8: 2012
A9: 5 | B9: I Know What I Am | C9: Band of Skulls | D9: Indie Rock | E9: 2009
A10: 5 | B10: Fight for Your Right | C10: Beastie Boys | D10: Hip-Hop/Rap | E10: 1986
A11: 1 | B11: Devils Haircut | C11: Beck | D11: Alternative | E11: 1996
A12: 5 | B12: The Bad Touch | C12: The Bloodhound Gang | D12: Pop/Dance/Electronic | E12: 1999
A13: 6 | B13: Burnin' for You | C13: Blue Oyster Cult | D13: Classic Rock | E13: 1981
... A46: 3 | B46: Blister In The Sun | C46: Violent Femmes | D46: Punk | E46: 1983
A50: Like | B50: 1
A51: 2 | B51: CITY OF ANGELS | C51: 24kGoldn | D51: Hip-Hop/Rap | E51: 2019
A52: 0 | B52: Far Too Near | C52: AFI | D52: Rock | E52: 2021
A53: 1 | B53: Aspiration | C53: After the Burial | D53: Metal | E53: 2009
A54: 8 | B54: Down In a Hole | C54: Alice in Chains | D54: Grunge | E54: 1992
A55: 2 | B55: Flavor of the Weak | C55: American Hi-Fi | D55: Punk | E55: 2001
A56: 2 | B56: We Are The One | C56: Anti-Flag | D56: Punk | E56: 2009
A57: 7 | B57: Heart of the Moment | C57: Asia | D57: Classic Rock | E57: 1982
A58: 7 | B58: Starlight | C58: BABYMETAL | D58: Metal | E58: 2018
A59: 4 | B59: Sick, Sick, Sick | C59: Bayside | D59: Alternative | E59: 2011
A60: 2 | B60: Prom Queen | C60: Beach Bunny | D60: Alternative | E60: 2018
A61: 6 | B61: Lonely Is The Night | C61: Billy Squire | D61: Classic Rock | E61: 1981
A62: 8 | B62: CHAMPION | C62: Bishop Briggs | D62: Alternative | E62: 2019
... A122: 1 | B122: Simplify | C122: Young the Giant | D122: Alternative | E122: 2018
A126: Nuetral | B126: 0
A127: 5 | B127: Shot in the Dark | C127: AC/DC | D127: Rock | E127: 2020
A128: 6 | B128: Running With The Wild Things | C128: Against The Current | D128: Pop-Rock | E128: 2016
A129: 2 | B129: Some Kind of Disaster | C129: All Time Low | D129: Emo | E129: 2020
A130: 4 | B130: Monsters | C130: All Time Low ft. Blackbear | D130: Emo | E130: 2020
A131: 7 | B131: Dreamchaser | C131: Amberian Dawn | D131: Metal | E131: 2008
A132: 7 | B132: Kokko - Eagle of Fire | C132: Amberian Dawn | D132: Metal | E132: 2009
A133: 6 | B133: Incubus | C133: Amberian Dawn | D133: Metal | E133: 2009
A134: 1 | B134: Let the Games Begin | C134: Anarbor | D134: Alternative | E134: 2010
A135: 8 | B135: Energy | C135: The Apples in Stereo | D135: Pop-Rock | E135: 2007
A136: 1 | B136: The Best | C136: AWOLNATION | D136: Alternative | E136: 2019
A137: 9 | B137: Hazy Shade of Winter | C137: The Bangles | D137: Rock | E137: 1987
...

Sheet RB2
B2: Song | C2: Artist | D2: Release Date | E2: Source | F2: Notes
B3: Visions | C3: Abnormality
B4: Let There Be Rock | C4: AC/DC
B5: Girl's Not Grey | C5: AFI
B6: You Oughta Know | C6: Alanis Morissette | D6: 45092 | E6: DLC | F6: DLC Single
B7: Man in the Box | C7: Alice in Chains | D7: 43020 | E7: DLC | F7: Part of "Alice in Chains Pack 03" and "Guitar Glory Pack"
B8: Ramblin' Man | C8: The Allman Brothers Band
B9: Get Clean | C9: Anarchy Club | D9: 42465 | E9: DLC | F9: Part of "30 Song Mega Pack"
B10: Almost Easy | C10: Avenged Sevenfold
B11: Shooting Star | C11: Bad Company
B12: Night Lies | C12: Bang Camaro | D12: 42465 | E12: DLC | F12: Part of "30 Song Mega Pack"
B13: So What'cha Want | C13: Beastie Boys
B14: E-Pro | C14: Beck
B15: White Wedding (Part 1) | C15: Billy Idol | D15: 45183 | E15: DLC | F15: DLC Single
B16: Rebel Girl | C16: Bikini Kill
B17: One Way or Another | C17: Blondie | D17: 42831 | E17: DLC | F17: DLC Single
B18: Tangled Up in Blue | C18: Bob Dylan
B19: Livin' on a Prayer | C19: Bon Jovi | D19: 41222 | E19: DLC | F19: Part of "Bon Jovi Greatest Hits" Album
B20: Shoulder to the Plow | C20: Breaking Wheel | D20: 42465 | E20: DLC | F20: Part of "30 Song Mega Pack"
B21: Hello There | C21: Cheap Trick | D21: 44917 | E21: DLC | F21: DLC Single
B22: Uncontrollable Urge | C22: Devo
B23: Feel the Pain | C23: Dinosaur Jr.
B24: Down with the Sickness | C24: Disturbed | D24: 42922 | E24: DLC | F24: DLC Single
B25: New Kid in School | C25: The Donnas
B26: Panic Attack | C26: Dream Theater
B27: Hungry Like the Wolf | C27: Duran Duran | D27: 43228 | E27: DLC | F27: DLC Single
B28: Pump It Up | C28: Elvis Costello | H28: Rock Band 2
B29: Go Your Own Way | C29: Fleetwood Mac | D29: 42915 | E29: DLC | F29: DLC SIngle | H29: 39705
B30: Everlong | C30: Foo Fighters | D30: 43090 | E30: DLC | F30: DLC Single and part of "Rock Band Hits Pack"
B31: We Got the Beat | C31: Go-Go's | D31: 43104 | E31: DLC | F31: DLC Single
B32: Alabama Getaway | C32: The Grateful Dead
B33: American Woman | C33: The Guess Who
B34: Shackler's Revenge | C34: Guns N' Roses
B35: PDA | C35: Interpol
B36: Mountain Song | C36: Jane's Addiction
B37: Aqualung | C37: Jethro Tull
B38: Bad Reputation | C38: Joan Jett | D38: 43048 | E38: DLC | F38: DLC Single
B39: The Middle | C39: Jimmy Eat World | D39: 43060 | E39: DLC | F39: DLC Single
B40: Any Way You Want It | C40: Journey
B41: Painkiller | C41: Judas Priest
...

Sheet LEGO RB
B2: Song | C2: Artist | D2: Release Date | E2: Source | F2: Notes
B3: Swing, Swing | C3: The All-American Rejects | D3: 42747 | E3: DLC | F3: DLC Single
B4: Monster | C4: The Automatic
B5: Aliens Exist | C5: Blink-182
B6: Song 2 | C6: Blur | D6: 45064 | E6: DLC | F6: DLC Single
B7: You Give Love a Bad Name | C7: Bon Jovi | D7: 40491 | E7: DLC | F7: Part of "Bon Jovi Greatest Hits" Album
B8: Thunder | C8: Boys Like Girls
B9: Summer of '69 | C9: Bryan Adams
B10: Kung Fu Fighting | C10: Carl Douglas
B11: Dreaming of You | C11: The Coral
B12: Accidentally in Love | C12: Counting Crows
B13: Let's Dance | C13: David Bowie
B14: Crocodile Rock | C14: Elton John
B15: The Final Countdown | C15: Europe | D15: 43097 | E15: DLC | F15: Part of "New Year's Eve 2017 Pack"
B16: Real Wild Child | C16: Everlife
B17: Breakout | C17: Foo Fighters
B18: Girls & Boys | C18: Good Charlotte
B19: Tick Tick Boom | C19: The Hives
B20: The Passenger | C20: Iggy Pop
B21: Dig | C21: Incubus
B22: I Want You Back | C22: Jackson 5 | D22: 43034 | E22: DLC | F22: DLC Single
B23: Fire | C23: The Jimi Hendrix Experience
B24: Ruby | C24: Kaiser Chiefs
B25: Walking on Sunshine | C25: Katrina & the Waves
B26: Naïve | C26: The Kooks
B27: Word Up! | C27: Korn
B28: Suddenly I See | C28: KT Tunstall
B29: Rooftops (A Liberation Broadcast) | C29: Lostprophets
B30: So What | C30: Pink
B31: Every Little Thing She Does Is Magic | C31: The Police
B32: Crash | C32: The Primitives
B33: We Are the Champions | C33: Queen | D33: 40120 | E33: DLC | F33: Part of "Queen Extravaganza Pack 01"
B34: We Will Rock You | C34: Queen | D34: 40120 | E34: DLC | F34: Part of "Queen Extravaganza Pack 01"
B35: Life Is a Highway | C35: Rascal Flatts
B36: Ghostbusters | C36: Ray Parker Jr.
B37: Stumble and Fall | C37: Razorlight
B38: Two Princes | C38: Spin Doctors | D38: 43160 | E38: DLC | F38: DLC Single
B39: Short and Sweet | C39: Spinal Tap
B40: Make Me Smile (Come Up and See Me) | C40: Steve Harley & Cockney Rebel
B41: In Too Deep | C41: Sum 41 | D41: 42782 | E41: DLC | F41: DLC Single
...

Sheet RB3
B2: Song | C2: Artist | D2: Release Date | E2: Source | F2: Notes
B3: Rehab | C3: Amy Winehouse | D3: 45253 | E3: DLC | F3: DLC Single
B4: Caught in a Mosh | C4: Anthrax
B5: One Armed Scissor | C5: At the Drive-In
B6: Beast and the Harlot | C6: Avenged Sevenfold | D6: 42852 | E6: DLC | F6: DLC Single
B7: Rock Lobster | C7: The B-52's
B8: Good Vibrations (Live) | C8: The Beach Boys
B9: In a Big Country | C9: Big Country | D9: 45288 | E9: DLC | F9: DLC Single
B10: Heart of Glass | C10: Blondie
B11: Get Up, Stand Up | C11: Bob Marley and the Wailers
B12: False Alarm | C12: The Bronx
B13: 25 or 6 to 4 | C13: Chicago
B14: Just Like Heaven | C14: The Cure
B15: Space Oddity | C15: David Bowie | D15: 45036 | E15: DLC | F15: DLC Single
B16: Smoke on the Water | C16: Deep Purple
B17: Foolin' | C17: Def Leppard
B18: Whip It | C18: Devo
B19: Rainbow in the Dark | C19: Dio | D19: 44875 | E19: DLC | F19: DLC Single
B20: Walk of Life | C20: Dire Straits
B21: China Grove | C21: The Doobie Brothers
B22: Break on Through (To the Other Side) | C22: The Doors
B23: King George | C23: Dover
B24: The Killing Moon | C24: Echo & The Bunnymen
B25: Saturday Night's Alright for Fighting | C25: Elton John | D25: 45288 | E25: DLC | F25: DLC Single
B26: Midlife Crisis | C26: Faith No More
B27: Hey Man, Nice Shot | C27: Filter
B28: Yoshimi Battles the Pink Robots Pt. 1 | C28: The Flaming Lips
B29: Cold as Ice | C29: Foreigner
B30: Radar Love | C30: Golden Earring
B31: Killing Loneliness | C31: H.I.M.
B32: The Power of Love | C32: Huey Lewis and the News
B33: Viva la Resistance | C33: Hypernova
B34: Oh My God | C34: Ida Maria
B35: Need You Tonight | C35: INXS
B36: Centerfold | C36: The J. Geils Band | D36: 45295 | E36: DLC | F36: DLC Single
B37: I Got You (I Feel Good) | C37: James Brown
B38: Been Caught Stealing | C38: Jane's Addiction
B39: Crosstown Traffic | C39: The Jimi Hendrix Experience
B40: I Love Rock N' Roll | C40: Joan Jett & The Blackhearts
B41: Imagine | C41: John Lennon
...

Sheet RBN
B2: Song | C2: Artist | D2: Release Date | E2: Source | F2: Notes
B3: !I | C3: !I!
B4: Latest Heartbreak | C4: 22-20s
B5: Just Hang On | C5: 2nd Thought
B6: Battles and Brotherhood | C6: 3 Inches of Blood | D6: 43699 | E6: DLC | F6: DLC Single
B7: All My Friends Are Crazy | C7: 500 Miles to Memphis
B8: Doomed | C8: 8 Inch Betsy
B9: Automatic Doors | C9: A'tris
B10: Secondary Gain | C10: Abraham Nixon
B11: Dr. Doom | C11: The Acacia Strain
B12: Hair Trigger | C12: The Acro-Brats | D12: 43059 | E12: DLC | F12: Part of "Rock Band 10th Anniversary Pack"
B13: Masters of Puppet Rock | C13: Action Action
B14: The Ones Who Get It | C14: Action Action
B15: Dance Battle Alpha | C15: Active Knowledge
B16: The Fractal Reason | C16: Active Knowledge
B17: Reality Down | C17: Active Knowledge
B18: Supertronic Lazering | C18: Active Knowledge
B19: Liberated by Blasphemy | C19: Adam Evil
B20: Bitten by the Rattlesnake | C20: Admiral of Black
B21: Skeleton | C21: Adora
B22: The Devil's in the Details | C22: Aesthetic Perfection
B23: Crusader | C23: AFD Shift
B24: Call to the Warrior | C24: Affiance
B25: Aspiration | C25: After the Burial | D25: 44280 | E25: DLC | F25: DLC Single and Temporarily Part of "Rivals Season 21 Pass"
B26: Berzerker | C26: After the Burial | D26: 43636 | E26: DLC | F26: DLC Single
B27: Cursing Akhenaten | C27: After the Burial
B28: My Frailty | C28: After the Burial
B29: Pendulum | C29: After the Burial
B30: Your Troubles Will Cease and Fortune Will Smile Upon You | C30: After the Burial
B31: Stay Up With Me | C31: After the Fall
B32: Thank You, Pain. | C32: The Agonist | D32: 44931 | E32: DLC | F32: Part of "Riffing In The New Year 2023"
B33: Broken Bones | C33: Aiden
B34: Hysteria | C34: Aiden
B35: Scavengers of the Damned | C35: Aiden
B36: Filthy Dog | C36: Aittala
B37: Numb | C37: Aittala
B38: Steven Wells (He Was the Greatest) | C38: Akira the Don
B39: Bleeder | C39: Alchemilla
B40: Back Through Time | C40: Alestorm | D40: 44490 | E40: DLC | F40: DLC Single
B41: Shipwrecked | C41: Alestorm | D41: 44350 | E41: DLC | F41: DLC Single and Temporarily Part of "Rivals Season 22 Pass"
...

Sheet Rock Band VR
B2: Song | C2: Artist | D2: Released Date | E2: Source | F2: Notes
B3: Walk This Way | C3: Aerosmith | D3: 41303 | E3: DLC | F3: Part of "Aerosmith's Greatest Dimension Pack"
B4: Running With The Wild Things | C4: Against The Current | D4: 44315 | E4: DLC | F4: DLC Single and Temporarily Part of "Rivals Season 21 Pass"
B5: Man in the Box | C5: Alice In Chains | D5: 39705 | E5: RB2 Export/DLC | F5: Export Has Expired, but re-released in "Alice in Chains Pack 03" and "Guitar Glory Pack"
B6: Black Seas | C6: Arctic Horror | D6: 42964 | E6: DLC | F6: Free DLC to Rivals Owners
B7: Lights Out | C7: AudioDamn!
B8: Beast and the Harlot | C8: Avenged Sevenfold | D8: 40477 | E8: RB3 Export/DLC | F8: Export Has Expired, but re-released as a Single
B9: Casual Party | C9: Band of Horses
B10: Promise Everything | C10: Basement | D10: 42824 | E10: DLC | F10: DLC Single
B11: (You're) Breakin' Up | C11: The Black Cheers | D11: 42964 | E11: DLC | F11: Free DLC to Rivals Owners
B12: Gold On The Ceiling | C12: The Black Keys | D12: 42936 | E12: DLC | F12: DLC Single
B13: Bored to Death | C13: blink-182 | D13: 42880 | E13: DLC | F13: DLC Single
B14: True Confessions | C14: Blondfire | D14: 42950 | E14: DLC | F14: DLC Single
B15: One Way or Another | C15: Blondie | D15: 39705 | E15: RB2 Export/DLC | F15: Export Has Expired, but re-released as a DLC single
B16: Livin' On A Prayer | C16: Bon Jovi | D16: 39705 | E16: RB2 Export/DLC | F16: Export Has Expired but re-released as part of "Bon Jovi's Greatest Hit" Album
B17: Church Bells | C17: Carrie Underwood | F17: Leaked Single?
B18: Postpone | C18: Catfish and the Bottlemen | D18: 42976 | E18: DLC | F18: DLC Single
B19: Birds | C19: Coldplay
B20: Suffragette City | C20: David Bowie | D20: 39406 | E20: RB1 Export/DLC | F20: Export Has Expired, but re-released as a DLC single and part of "Rock Band Hits Pack"
B21: Down With The Sickness | C21: Disturbed | D21: 39705 | E21: RB2 Export/DLC | F21: Export Has Expired, but re-released as a DLC single
B22: Through The Fire And Flames | C22: Dragonforce | D22: 40631 | E22: DLC | F22: DLC Single and part of "Rock Band Hits Pack"
B23: Pull Me Under | C23: Dream Theater | D23: 42894 | E23: DLC | F23: DLC Single
B24: The Final Coutdown | C24: Europe | D24: 40120 | E24: LEGO Export/DLC | F24: Export Has Expired but re-released in the "New Year's Eve 2017 Pack"
B25: Go Your Own Way | C25: Fleetwood Mac | D25: 39705 | E25: RB2 Export/DLC | F25: Export Has Expired, but re-released as a DLC single and part of "Rock Band Hits Pack"
B26: Everlong | C26: Foo Fighters | D26: 39705 | E26: RB2 Export/DLC | F26: Export Has Expired, but re-released as a DLC single
B27: Cirice | C27: Ghost | D27: 42922 | E27: DLC | F27: DLC Single
B28: We Got The Beat | C28: The Go-Go's | D28: 39705 | E28: RB2 Export/DLC | F28: Export Has Expired, but re-released as a DLC single | I28: Rock Band VR
B29: Holiday | C29: Green Day | D29: 40337 | E29: Green Day Export/DLC | F29: Export Has Expired, but was Re-Released as a Part of "American Idiot" Album | I29: 42817
B30: You & Me | C30: The Hunna | D30: 42880 | E30: DLC | F30: DLC Single
B31: The Middle | C31: Jimmy Eat World | D31: 39705 | E31: RB2 Export/DLC | F31: Export Has Expired, but re-released as a DLC single
B32: Bad Reputation | C32: Joan Jett | D32: 39705 | E32: RB2 Export/DLC | F32: Export Has Expired, but re-released as a DLC single
B33: Glass House | C33: Kaleo | D33: 42838 | E33: DLC | F33: DLC Single
B34: When You Were Young | C34: The Killers | D34: 39406 | E34: RB1 Export/DLC | F34: Export Has Expired, but re-released as a DLC single
B35: Use Somebody | C35: Kings of Leon | D35: 42817 | E35: DLC | F35: DLC Single
B36: Maps | C36: Maroon 5 | F36: Leaked Single?
B37: Hanger 18 | C37: Megadeth | D37: 40218 | E37: DLC | F37: Part of "Rust in Peace" Album
B38: I Will Wait | C38: Mumford & Sons | D38: 42817 | E38: DLC | F38: DLC Single and part of "Guitar Glory Pack"
B39: Smells Like Teen Spirit | C39: Nirvana | D39: 40148 | E39: DLC | F39: Part of "Nirvana Pack 02"
B40: Champagne Supernova | C40: Oasis | D40: 42845 | E40: DLC | F40: DLC Single
B41: Counting Stars | C41: OneRepublic | D41: 42817 | E41: DLC | F41: DLC Single
...

Sheet Rock Band VR DLC
B2: Song | C2: Artist | D2: Released Date | E2: Source | F2: Notes | G2: Song
B3: Angel | C3: Aerosmith | D3: 42726 | E3: DLC | F3: Part of "Aerosmith Hits Pack 03"
B4: Crazy | C4: Aerosmith | D4: 42726 | E4: DLC | F4: Part of "Aerosmith Hits Pack 03"
B5: I Don't Want to Miss a Thing | C5: Aerosmith | D5: 42726 | E5: DLC | F5: Part of "Aerosmith Hits Pack 03"
B6: Janie's Got A Gun | C6: Aerosmith | D6: 42726 | E6: DLC | F6: Part of "Aerosmith Hits Pack 03"
B7: Living On The Edge | C7: Aerosmith | D7: 42726 | E7: DLC | F7: Part of "Aerosmith Hits Pack 03"
B8: Rag Doll | C8: Aerosmith | D8: 42726 | E8: DLC | F8: Part of "Aerosmith Hits Pack 03"
B9: You Give Love a Bad Name | C9: Bon Jovi | D9: 40120 | E9: LEGO Export/DLC | F9: Export Has Expired but re-released as part of "Bon Jovi's Greatest Hit" Album
B10: What's My Age Again? | C10: blink-182 | D10: 40099 | E10: DLC | F10: DLC Single
B11: Ex's & Oh's | C11: Elle King | D11: 42353 | E11: DLC | F11: Part of "Off The Charts 02
B12: My Songs Know What You Did In The Dark (Light Em Dark) | C12: Fall Out Boy | D12: 42451 | E12: DLC | F12: Part of "Off The Charts Pack 03"
B13: The Pretender | C13: Foo Fighters | D13: 40120 | E13: DLC | F13: Part of "Foo Fighters Pack 03"
B14: Basket Case | C14: Green Day | D14: 40337 | E14: Green Day Export/DLC | F14: Export Has Expired, but was Re-released as a Part of "American Idiot" Album
... B24: Seven Nation Army | C24: The White Stripes | D24: 40246 | E24: DLC | F24: Part of "The White Stripes Pack 02"
B27: Songs Released | C27: =COUNT(D:D) -> 22
B28: Total Songs | C28: 22
B29: Percent Complete | C29: =IFERROR(__xludf.DUMMYFUNCTION("TO_PERCENT(C27/C28)"),1.0) -> 1

Sheet Dropmix
A1: Dro
B2: Song | C2: Artist | D2: Released Date | E2: Source | F2: Notes
B3: Take Over Controls (Ft. Eva Simons) | C3: Afrojack
B4: Am I Wrong (Ft. Schoolboy Q) | C4: Anderson.Paak
B5: More Than You Know | C5: Axwell /\ Ingrosso
B6: Gimme Chocolate!! | C6: Babymetal | D6: 42283 | E6: DLC | F6: DLC Single
B7: Who Let The Dogs Out | C7: Baha Men
B8: Pompeii | C8: Bastille | D8: 42577 | E8: DLC | F8: DLC Single
B9: Poison | C9: Bell Biv Devoe
B10: Satisfaction | C10: Benny Benassi presents The Biz
B11: Save A Horse (Ride A Cowboy) | C11: Big & Rich | D11: 43060 | E11: DLC | F11: DLC Single and Temporarily Part of "Rivals Season 3 Pass"
B12: Boom Boom Pow | C12: The Black Eyed Peas
B13: All The Small Things | C13: blink-182 | D13: 39462 | E13: DLC | F13: DLC Single
B14: Heart of Glass | C14: Blondie | D14: 40477 | E14: RB3 Export | F14: Export Has Expired
B15: 24K Magic | C15: Bruno Mars | D15: 42696 | E15: DLC | F15: DLC Single
B16: Short Skirt/Long Jacket | C16: Cake | D16: 42283 | E16: RB4 | F16: On-Disc Song
B17: Call Me Maybe | C17: Carly Rae Jepsen | D17: 41240 | E17: DLC | F17: DLC Single
B18: Blown Away | C18: Carrie Underwood | D18: 41362 | E18: DLC | F18: Part of "Going Country Pack 09"
B19: Closer (Ft. Halsey) | C19: The Chainsmokers | D19: 42670 | E19: DLC | F19: DLC SIngle
B20: Attention | C20: Charlie Puth | D20: 43083 | E20: DLC | F20: Part of "Off The Charts 06" and "Rock Band Hits Pack"
B21: Heartbeat | C21: Childish Gambino
B22: The Mother We Share | C22: CHVRCHES | D22: 44812 | E22: DLC | F22: DLC Single and Temporarily Part of "Rivals Season 28 Pass"
B23: Brick House | C23: Commodores | D23: 43139 | E23: DLC | F23: DLC Single, and temporarily part of "Season 4 Spotlight Pass Plus"
B24: Up All Night | C24: Connecticut River Boys
B25: Me Rehuso | C25: Danny Ocean
B26: Flutter Fly (From The Pyre Original Soundtrack) | C26: Darren Korb
B27: Down With the Sickness | C27: Disturbed | D27: 39705 | E27: RB2 Export/DLC | F27: Export Has Expired, but re-released as a single
B28: All I Do Is Win (Ft. T-Pain) | C28: DJ Khaled
B29: Guitek | C29: DJ Steve Porter
B30: Jolene | C30: Dolly Parton | D30: 44637 | E30: DLC | F30: DLC Single and Temporarily Part of "Rivals Season 25 Pass"
B31: Barbra Streisand | C31: Duck Sauce
B32: September | C32: Earth, Wind, and Fire | D32: 42283 | E32: DLC | F32: DLC Single
B33: Sing | C33: Ed Sheeran | D33: 42325 | E33: DLC | F33: Available only in the "Ed Sheeran SIng Special Edition" Bundle
B34: When Things Fall Apart | C34: Eddie Japan
B35: Burn | C35: Ellie Goulding
B36: Unbelievable | C36: EMF | D36: 40792 | E36: DLC | F36: Re-record available as a DLC Singlr
B37: The Final Coutdown | C37: Europe | D37: 40120 | E37: LEGO Export/DLC | F37: Export Has Expired but re-released in the "New Year's Eve 2017 Pack"
B38: Bring Me To Life (Ft. Paul McCoy) | C38: Evanescence | D38: 39980 | E38: DLC | F38: Part of "Evanescence Pack 01"
B39: Centuries | C39: Fall Out Boy | D39: 42283 | E39: RB4 | F39: On-Disc Song
B40: Like A G6 (Ft. The Cataracs & Dev) | C40: Far East Movement
...

Sheet Fuser
B2: Song | C2: Artist | D2: Released Date | E2: Source | F2: Notes
B3: In Da Club | C3: 50 Cent
B4: Can I Kick It? | C4: A Tribe Called Quest
B5: Take On Me | C5: A-ha | D5: 40547 | E5: DLC | F5: DLC Single
B6: The Sign | C6: Ace of Base | D6: 43053 | E6: DLC | F6: Part of "Back in the '90's Pack 01"
B7: Daniel Wiggy | C7: Agent 001
B8: Rehab | C8: Amy Winehouse | D8: 40477 | E8: RB3 Export/DLC | F8: Export Has Expired, but re-released as a DLC single
B9: Blah Blah Blah | C9: Armin van Buuren
B10: Sweet But Psycho | C10: Ava Max
B11: Yo Perreo Sola | C11: Bad Bunny
B12: Where's Your HEad At | C12: Basement Jaxx
B13: Sin Pijama | C13: Becky G & Natti Natasha
B14: Satisfaction | C14: Benny Benassi presents The Biz
B15: Bad Guy | C15: Billie Eilish | D15: 43818 | E15: DLC | F15: Part of "Headliners Pack" and temporaraily part of "Apple Music Spotlight Pass"
B16: Sequence Her | C16: Black Light Odyssey
B17: (Don't Fear) The Reaper | C17: Blue Oyster Cult | D17: 39406 | E17: RB1 Export/DLC | F17: Export Has Expired but Re-Released in "Solid '70s Pack 01"
B18: My Perogative | C18: Bobby Brown
B19: Mud On The Tires | C19: Brad Paisley | D19: 39798 | E19: DLC | F19: Part of "Rock Band Country Track Pack 01" and part of "Going Country Pack 01"
B20: Dot Calm | C20: Cade7
B21: Bodak Yellow | C21: Cardi B
B22: Call Me Maybe | C22: Carly Rae Jepsen | D22: 41240 | E22: DLC | F22: DLC Single
B23: Don't Let Me Down | C23: The Chainsmokers ft. Daya
B24: Bloom | C24: Charm Syndicate
B25: Summertime Magic | C25: Childish Gambino
B26: Rock the Casbah | C26: The Clash
B27: Clocks | C27: Coldplay | D27: 40834 | E27: DLC | F27: Part of "Coldplay Collection 01" and part of "Rock Band Hits Pack 03"
B28: Rupture Academy | C28: CrackCase
B29: Ghosts 'n' Stuff | C29: deadmau5 ft. Rob Swire
B30: X Gon' Give It To Ya | C30: DMX
B31: Jolene | C31: Dolly Parton | D31: 44637 | E31: DLC | F31: DLC Single and Temporarily Part of "Rivals Season 25 Pass"
B32: Hot Stuff | C32: Donna Summer
B33: Don't Start Now | C33: Dua Lipa | D33: 43930 | E33: DLC | F33: DLC Single and temporaraly part of "Season 16 Spotlight Pass Plus"
B34: Summer Hair | C34: Eddie Japan
B35: Don't Sweat the Technique | C35: Eric B. & Rakim
B36: The Rockafeller Shank | C36: Fatboy Slim
B37: G.D.F.R | C37: Flo Rida ft. Sage the Gemini & Lookas
B38: The Message (2012) | C38: Grand Master Melle Mel
B39: This Isn't Enough | C39: Greg LeBeau
B40: Tongue Tied | C40: Grouplove | D40: 42283 | E40: RB4 | F40: On-Disc Song
B41: Thunder | C41: Imagine Dragons | D41: 43083 | E41: DLC | F41: Part of "Off the Charts Pack 06"
...

Sheet Fuser DLC
B2: Song | C2: Artist | D2: Released Date | E2: Source | F2: Notes
B3: A Lot | C3: 21 Savage
B4: Mood | C4: 24kGolldn ft. Iann Dior
B5: Take Over Control | C5: Afrojack ft. Eva Simons
B6: Ironic | C6: Alanis Morissette | D6: 40092 | E6: DLC | F6: DLC SIngle
B7: Leave a Little Love | C7: Alesso & Armin van Buuren
B8: 1 Thing | C8: Amerie
B9: Me Gusta | C9: Anitta ft. Cardi B and Myke Towers
B10: Among the Living | C10: Anthrax | D10: 40449 | E10: DLC | F10: Part of "Anthrax Pack 01"
B11: Your Love (9PM) | C11: ATB, Topic, A7S
B12: Kings & Queens | C12: Ava Max
B13: Loop Pack 06 | C13: Basra Khan
B14: Royce Please | C14: Beast Business
B15: Venus | C15: Bananarama
B16: Baby, I'm Jealous | C16: Bebe Rexha ft. Doja Cat
B17: Poison | C17: Bell Biv DeVoe
B18: Loop Pack 5 | C18: Bignums
B19: Larry's Place (Part II) | C19: Bignums
B20: Therefore I Am | C20: Billie Eilish | D20: 44308 | E20: DLC | F20: DLC Single and Temporarily Part of "Rivals Season 21 Pass"
B21: Holding Out for a Hero | C21: Bonnie Tyler
B22: Soon May the Wellerman Come | C22: Cap'n Spicy Dill
B23: Murder She Wrote | C23: Chaka Demus & Pliers
B24: Tubthumping | C24: Chumbawamba | D24: 40708 | E24: DLC | F24: DLC Single
B25: Should I Stay or Should I Go | C25: The Clash | D25: 39406 | E25: RB1 Export | F25: Export Has Expired
B26: Linger | C26: The Cranberries | D26: 39959 | E26: DLC | F26: DLC Single
B27: Firday I'm in Love | C27: The Cure | D27: 42283 | E27: RB4 | F27: On-Disc Song
B28: Bop | C28: DaBaby
B29: Con Calma | C29: Daddy Yankee ft. Snow
B30: Sandstorm | C30: Darude
B31: Let's Love | C31: David Guetta & Sia
B32: Where Them Girls At | C32: David Guetta ft. Nicki Minaj & Flo Rida
B33: Groove Is in the Heart | C33: Deee-Lite | D33: 44924 | E33: DLC | F33: DLC Single
B34: Smoke on the Water | C34: Deep Purple | D34: 40477 | E34: RB3 Export | F34: Export Has Expired
B35: Days Go By | C35: Dirty Vegas
B36: Latch | C36: Disclosure ft. Sam Smith
B37: Loop Pack 12 | C37: Dissentor
B38: Loco Contigo | C38: DJ Snake, J Balvin & Tyga
B39: New Rules | C39: Dua Lipa
B40: Kiss and Make Up | C40: Dua Lipa & Blackpink
B41: Lips Like Sugar | C41: Echo & the Bunnymen
...

Sheet Fortnite Festival
B2: Song | C2: Artist | D2: Release Date | E2: Source | F2: Notes
B3: Dirty Little Secret | C3: The All-American Rejects | D3: 39441 | E3: DLC | F3: DLC Single
B4: Pompeii
B5: Poison | C5: Bell Biv Devoe
B6: Bad Guy | C6: Billie Eilish | D6: 43818 | E6: DLC | F6: Part of "Headliners Pack" and temporaraily part of "Apple Music Spotlight Pass"
B7: Zombie | C7: The Cranberries | D7: 39959 | E7: DLC | F7: DLC Single
B8: Cake By The Ocean | C8: DNCE | D8: 42472 | E8: DLC | F8: Part of "Off The Charts 04"
B9: Brace For Chaos | C9: Epic Games
B10: Butter Barn Hoedown | C10: Epic Games
B11: Run It | C11: Epic Games
B12: Switch Up | C12: Epic Games
B13: Take Me Higher | C13: Epic Games
B14: My Songs Know What You Did In The Dark (Light Em Up) | C14: Fall Out Boy | D14: 42451 | E14: DLC | F14: Part of "Off The Charts Pack 03"
B15: Dog Days Are Over | C15: Florence + The Machine | D15: 41035 | E15: DLC | F15: DLC Single
B16: Highway Tune | C16: Greta Van Fleet
B17: Heat Waves | C17: Glass Animals
B18: Thunder | C18: Imagine Dragons | D18: 43083 | E18: DLC | F18: Part of "Off the Charts Pack 06"
B19: I | C19: Kendrick Lamar
B20: Mr. Brightside | C20: The Killers | D20: 39777 | E20: DLC | F20: Part of "The Killers Pack 01" and "Rock Band Hits Pack"
B21: Suddenly I See | C21: KT Tunstall | D21: 40120 | E21: LEGO Export | F21: Export Has Expired
B22: Bad Romance | C22: Lady Gaga | D22: 40253 | E22: DLC | F22: Part of "Lady Gaga Pack 1"
B23: Party Rock Anthem | C23: LMFAO Ft. Lauren Bennett & Goonrock | D23: 42733 | E23: DLC | F23: Part of "New Year's Eve 2016 Pack"
B24: Emo Girl | C24: Machine Gun Kelly Ft. Willow
B25: The Search | C25: NF
B26: Hand That Feeds You | C26: Nine Inch Nails | D26: 39406 | E26: RB1 Export/DLC | F26: Export Has Expired, but was re-released as a Single
B27: Vampire | C27: Olivia Rodrigo
B28: Counting Stars | C28: OneRepublic | D28: 42817 | E28: DLC | F28: DLC Single
B29: Gangnam Style | C29: PSY
B30: Go With The Flow | C30: Queens of the Stone Age | D30: 39406 | E30: RB1 Export/DLC | F30: Export Has Expired but has been released a Part of "Rock Band Rewind Pack 01" and "Rock Band 15th Anniversary"
B31: Stiches | C31: Shawn Mendes
B32: Cradles | C32: Sub Urban | D32: 44070 | E32: DLC | F32: DLC Single and Temporarily Part of "Rivals Season 18 Season Pass"
B33: Can't Feel My Face | C33: The Weeknd | D33: 42353 | E33: DLC | F33: Part of "Off The Charts 02"
B34: Blinging Lights | C34: The Weeknd
B35: The Hills | C35: The Weeknd | D35: 42471 | E35: DLC | F35: Part of "Off the Charts 04"
B36: Save Your Tears | C36: The Weeknd
B37: Take My Breath | C37: The Weeknd | D37: 44070 | E37: DLC | F37: DLC Single
B38: Buddy Holly | C38: Weezer | D38: 39434 | E38: DLC | F38: DLC Single
B39: Seven Nation Army | C39: The White Stripes | D39: 40246 | E39: DLC | F39: Part of "The White Stripes Pack 02"
B40: Nothing's Alright | C40: Witchgang
B43: Songs Released | C43: =COUNT(D:D) -> 20
...

Sheet GH1
B2: Song | C2: Artist | D2: Release Date | E2: Source | F2: Notes
B3: Callout | C3: The Acro-Bats
B4: Behind the Mask | C4: Anarchy Club
B5: The Breaking Wheel | C5: Artillery
B6: Cochise* | C6: Audioslave
B7: Caveman Rejoice | C7: The Bags
B8: Infected* | C8: Bad Religion
B9: Fire it Up | C9: Black Label Society
B10: Iron Man* | C10: Black Sabbath
B11: Godzilla* | C11: Blue Oyster Cult | D11: 40204 | E11: DLC | F11: DLC Single and part of "Guitar Glory Pack"
B12: More Than A Feeling* | C12: Boston | D12: 39532 | E12: DLC | F12: Part of "Boston Pack 01"
B13: Heart Full of Black* | C13: Burning Brides
B14: Sail Your Ship By | C14: Count Zero
B15: Crossroads* | C15: Cream
B16: Ziggy Stardust* | C16: David Bowie | D16: 40568 | E16: DLC | F16: Part of "David Bowie Pack 02"
B17: Smoke On the Water* | C17: Deep Purple | D17: 40477 | E17: RB3 Export | F17: Export Has Expired
B18: Fly on the Wall | C18: Din
B19: Take It Off* | C19: The Donnas | D19: 44630 | E19: DLC | F19: DLC Single and Temporarily Part of "Rivals Season 25 Pass"
B20: Decontrol | C20: Drist
B21: Frankenstein* | C21: The Edgar Winter Group | D21: 40925 | E21: DLC | F21: DLC Single
B22: Hey You* | C22: The Exies
B23: Take Me Out* | C23: Franz Ferdinand | D23: 39938 | E23: DLC | F23: Part of "Franz Ferdinand Pack 01" and "Guitar Glory Pack"
B24: Get Ready 2 Rokk | C24: Freezepop | D24: 40065 | E24: DLC | F24: Part of "Freezepop Pack 01" and "30 Song Mega Pack"
B25: Cheat on the Church | C25: Graveyard BBQ | D25: 43059 | E25: DLC | F25: Part of "Rock Band 10th Anniversary Pack"
B26: Unsung* | C26: Helmet
B27: Hey | C27: Honest Bob and the Factory-to-Dealer Incentives | D27: 40798 | E27: RBN | F27: Not compatible with RB4
B28: Stellar* | C28: Incubus | D28: 44616 | E28: DLC | F28: DLC Single and Temporarily Part of "Rivals Season 25 Pass"
B29: Spanish Castle Magic* | C29: Jimi Hendrix | D29: 40267 | E29: DLC | F29: RB has Vocals Included and is Part of "Axis: Bold as Love" Album
B30: I Love Rock N' Roll* | C30: Joan Jett and the Blackhearts | D30: 40477 | E30: RB3 Export | F30: Export Has Expired
B31: You've Got Another Thing Coming* | C31: Judas Priest | D31: 39560 | E31: DLC | F31: Part of "Screaming for Vengence" album and Metal Track Pack
B32: Farewell Myth | C32: Made in Mexico
B33: Symphony of Destruction* | C33: Megadeth | D33: 40960 | E33: DLC | F33: Part of "Megadeth Pack 01"
B34: Story of My Love | C34: The Model Sons
B35: Guitar Hero | C35: Monkey Steals the Peach
B36: Ace of Spades* | C36: Motorhead | D36: 39705 | E36: RB2 Export | F36: Export Has Expired, but Reliscened as a Single
B37: Bark at the Moon* | C37: Ozzy Osbourne | D37: 40694 | E37: DLC | F37: Available exclusively in the "Ozzy 8-Pack"
B38: Cowboys From Hell* | C38: Pantera | D38: 42283 | E38: DLC | F38: RB has "Live From Monsters in Moscow" Version as a Single and part of "Guitar Glory Pack"
B39: Killer Queen* | C39: Queen | D39: 40106 | E39: DLC | F39: Part of "Queen Pack 01" and "Queen RB3 Enhanced Pack"
B40: No One Knows* | C40: Queens of the Stone Age | D40: 40477 | E40: RB3 Export | F40: Export Has Expired
B41: I Wanna Be Sedated* | C41: The Ramones | D41: 40477 | E41: RB3 Export/DLC | F41: Export Has Expired but was re-released in "Solid '70's Pack 2" and in "Guitar Glory Pack"
...

Sheet GH2
B2: Song | C2: Artist | D2: Release Date | E2: Source | F2: Notes
B3: Laughtrack | C3: The Acro-Brats
B4: Last Child | C4: Aerosmith
B5: Billion Dollar Babies | C5: Alice Cooper | D5: 39952 | E5: DLC | F5: Live Version part of "Alice Cooper Pack 01"
B6: Them Bones | C6: Alice in Chains | D6: 43020 | E6: DLC | F6: Part of "Alice in Chains Pack 03"
B7: Jessica | C7: The Allman Brothers Band | D7: 41233 | E7: DLC | F7: DLC Single
B8: Six | C8: All That Remains
B9: Collide | C9: Anarchy Club | D9: 43059 | E9: DLC | F9: Part of "Rock Band 10th Anniversary Pack"
B10: Madhouse | C10: Anthrax | D10: 40449 | E10: DLC | F10: Live Version part of "Anthrax Pack 01"
B11: Mr. Fix It | C11: The Amazing Crowns
B12: Beast and the Harlot | C12: Avenged Sevenfold | D12: 40477 | E12: RB3 Export/DLC | F12: Export Has Expired, but re-released as a Single
B13: Push Push (Lady Lightning) | C13: Bang Camaro | D13: 42465 | E13: DLC | F13: Part of "30 Song Mega Pack"
B14: War Pigs | C14: Black Sabbath | D14: 39420 | E14: DLC | F14: Cover Part of "Black Sabbath Pack 01"
B15: One for the Road | C15: The Breaking Wheel
B16: Gemini | C16: Brian Kahanek | D16: 41242 | E16: RBN | F16: Not compatible with RB4
B17: Jordan | C17: Buckethead
B18: Who Was in My Room Last Night? | C18: The Butthole Surfers
B19: Radium Eyes | C19: Count Zero
B20: Surrender | C20: Cheap Trick | D20: 40792 | E20: DLC | F20: Part of "Cheap Trick Pack 01"
B21: Mother | C21: Danzig
B22: Hush | C22: Deep Purple
B23: Thunderhorse | C23: Dethklok
B24: Misirlou | C24: Dick Dale
B25: Arterial Black | C25: Drist
B26: The New Black | C26: Every Time I Die
B27: Monkey Wrench | C27: Foo Fighters | D27: 39763 | E27: DLC | F27: Part of "The Colour and the Shape" Album
B28: Less Talk More Rokk | C28: Freezepop | D28: 40066 | E28: DLC | F28: Part of "Freezepop Pack 01" and "30 Song Mega Pack" | I28: Guitar Hero II
B29: Sweet Child o' Mine | C29: Guns N' Roses | I29: 39028
B30: Crazy on You | C30: Heart | D30: 43440 | E30: DLC | F30: DLC Single and Temporarily Part of "Rivals Season 9 Pass"
B31: Soy Bomb | C31: Honest Bob and the Factory-to-Dealer Incentives | D31: 43059 | E31: DLC | F31: Part of "Rock Band 10th Anniversary Pack"
B32: The Trooper | C32: Iron Maiden | D32: 39973 | E32: DLC | F32: Part of "Iron Maiden Pack 01"
B33: Search and Destroy | C33: Iggy Pop and the Stooges
B34: Stop! | C34: Jane's Addiction | D34: 42647 | E34: DLC | F34: DLC Single
B35: Carry On Wayward Son | C35: Kansas | D35: 39705 | E35: RB2 Export/DLC | F35: Export Has Expired but Re-Released in the "Solid '70s Pack 01"
B36: Strutter | C36: Kiss | D36: 40659 | E36: DLC | F36: Live Version as a DLC Single
B37: Laid to Rest | C37: Lamb of God | D37: 39777 | E37: DLC | F37: Part of "Metal Track Pack" and as a DLC Single
B38: Raw Dog | C38: The Last Vegas
B39: Carry Me Home | C39: The Living End
B40: Free Bird | C40: Lynyrd Skynyrd | D40: 40477 | E40: RB3 Export/DLC | F40: Export Has Expired, but re-released as a Single
B41: Yes We Can | C41: Made in Mexico
...

Sheet GH2 DLC
B2: Song | C2: Artist | D2: Release Date | E2: Source | F2: Notes
B3: Ex's and Oh's | C3: Atreyu
B4: Infected* | C4: Bad Religion
B5: You Should Be Ashamed of Myself | C5: The Bled
B6: Smoke on the Water* | C6: Deep Purple | D6: 40477 | E6: RB3 Export | F6: Export Has Expired
B7: Take It Off* | C7: The Donnas | D7: 44630 | E7: DLC | F7: DLC Single and Temporarily Part of "Rivals Season 25 Pass"
B8: The State of Massachusetts | C8: Dropkick Murphys
B9: Frankenstein* | C9: The Edgar Winter Group | D9: 40925 | E9: DLC | F9: DLC Single
B10: Hey You* | C10: The Exies
B11: Stellar* | C11: Incubus | D11: 44616 | E11: DLC | F11: DLC Single and Temporarily Part of "Rivals Season 25 Pass"
B12: You've Got Another Thing Comin'* | C12: Judas Priest | D12: 39560 | E12: DLC | F12: Part of "Screaming for Vengence" album and Metal Track Pack
B13: Sin Documentos | C13: Los Rodríguez
B14: Memories of the Grove | C14: Maylene and the Sons of Disaster
B15: Ace of Spades* | C15: Motörhead | D15: 39705 | E15: RB2 Export/DLC | F15: Export Has Expired, but has been Re-Liscened as a Single
B16: Famous Last Words | C16: My Chemical Romance | D16: 42528 | E16: DLC | F16: DLC Single
B17: Teenagers | C17: My Chemical Romance | D17: 41268 | E17: DLC | F17: Part of "My Chemical Romance Pack 01"
B18: This Is How I Disappear | C18: My Chemical Romance
B19: Bark at the Moon* | C19: Ozzy Osbourne | D19: 40694 | E19: DLC | F19: Available exclusively in the "Ozzy 8-Pack"
B20: Sept | C20: Pleymo
B21: Bury the Hatchet | C21: Protest the Hero
B22: Killer Queen* | C22: Queen | D22: 40106 | E22: DLC | F22: Part of "Queen Pack 01" and "Queen RB3 Enhanced Pack"
B23: I Wanna Be Sedated* | C23: The Ramones | D23: 40477 | E23: RB3 Export/DLC | F23: Export Has Expired but was re-released in "Solid '70's Pack 2" and in "Guitar Glory Pack"
B24: Higher Ground* | C24: Red Hot Chili Peppers | F24: RB has Stevie Wonder Version
B25: Exile | C25: Soilwork
B26: Detonation | C26: Trivium
I28: Guitar Hero II DLC
B29: Songs Released | C29: =COUNT(D:D) -> 11 | I29: Apr. 11, 2007 - Nov. 29,2007
B30: Total Songs | C30: 24
B31: Percent Complete | C31: =IFERROR(__xludf.DUMMYFUNCTION("TO_PERCENT(C29/C30)"),0.4583333333333333) -> 0.45833333
B33: *Cover version

Sheet GH3
B2: Song | C2: Artist | D2: Release Date | E2: Source | F2: Notes
B3: Same Old Song and Dance | C3: Aerosmith
B4: Miss Murder | C4: AFI | D4: 40066 | E4: DLC | F4: DLC Single
B5: School's Out* | C5: Alice Cooper | D5: 39952 | E5: DLC | F5: Live Version Part of "Alice Cooper Pack 01"
B6: Impulse | C6: An Endless Sporadic | D6: 40864 | E6: RBN | F6: Not compatible with RB4
B7: Minus Celsius | C7: Backyard Babies
B8: Sabotage | C8: Beastie Boys | D8: 39406 | E8: RB1 Export/DLC | F8: Export Has Expired but has been released a Part of "Rock Band Rewind Pack 01" and "Rock Band 15th Anniversary"
B9: Paranoid* | C9: Black Sabbath | D9: 39406 | E9: RB1 | F9: Cover that was never Exportable
B10: Helicopter | C10: Bloc Party
B11: Cities on Flame with Rock and Roll* | C11: Blue Öyster Cult
B12: Go That Far | C12: Bret Michaels Band
B13: Sunshine of Your Love* | C13: Cream
B14: Holiday in Cambodia* | C14: Dead Kennedys | D14: 39770 | E14: DLC | F14: Part of "Dead Kennedys Pack 01" and "Classic Rock Track Pack"
B15: Hier kommt Alex | C15: Die Toten Hosen | D15: 39588 | E15: DLC | F15: DELISTED
B16: Stricken | C16: Disturbed | D16: 39945 | E16: DLC | F16: DLC Single
B17: Nothing for Me Here | C17: Dope
B18: Through the Fire and Flames | C18: DragonForce | D18: 40631 | E18: DLC | F18: DLC Single and part of "Rock Band Hits Pack"
B19: Cliffs of Dover | C19: Eric Johnson
B20: F.C.P.R.E.M.I.X. | C20: The Fall of Troy | D20: 44854 | E20: DLC | F20: DLC SIngle and Temporarily Part of "Rivals Season 28 Pass"
B21: Slow Ride | C21: Foghat | D21: 43041 | E21: DLC | F21: Part of 'Solid '70's Pack 2"
B22: In the Belly of a Shark | C22: Gallows
B23: Welcome to the Jungle | C23: Guns N' Roses
B24: Barracuda | C24: Heart | D24: 40757 | E24: DLC | F24: DLC Single
B25: I'm in the Band | C25: Hellacopters
B26: Avalancha | C26: Héroes del Silencio
B27: Take This Life | C27: In Flames
B28: The Number of the Beast | C28: Iron Maiden | D28: 39455 | E28: DLC | F28: Cover as a single and Original is Part of "Iron Maiden Pack 01" | I28: Guitar Hero III: Legends of Rock
B29: Ruby | C29: Kaiser Chiefs | D29: 40120 | E29: LEGO Export | F29: Export Has Expired | I29: 39383
B30: When You Were Young | C30: The Killers | D30: 39406 | E30: RB1 Export/DLC | F30: Export Has Expired but has been re-released as a DLC Single
B31: My Curse | C31: Killswitch Engage | D31: 39672 | E31: DLC | F31: Part of "Roadrunner Records Pack 01"
B32: Rock and Roll All Nite | C32: Kiss | D32: 40659 | E32: DLC | F32: RB has live version as a DLC Single
B33: Down 'n Dirty | C33: L.A. Slum Lords
B34: Closer | C34: Lacuna Coil | D34: 39770 | E34: DLC | F34: Part of "Century Media Girls of Metal Pack" and Metal Track Pack"
B35: Metal Heavy Lady | C35: Lions
B36: Cult of Personality | C36: Living Colour | D36: 41150 | E36: Blitz/DLC | F36: Part of Rock Band Blitz and as a DLC Single
B37: Monsters | C37: Matchbook Romance
B38: One | C38: Metallica
B39: Mississippi Queen | C39: Mountain | D39: 39406 | E39: RB1 Export | F39: Export Has Expired, and it's a cover
B40: Knights of Cydonia | C40: Muse | D40: 44805 | E40: DLC | F40: Part of "Muse Pack 01" and Temporarily Part of "Rivals Season 28 Pass"
B41: Mauvais Garçon | C41: Naast
...

Sheet GH3 DLC
B2: Song | C2: Artist | D2: Release | E2: Source | F2: Notes
B3: Dream On | C3: Aerosmith | D3: 41303 | E3: DLC | F3: Live Version is part of "Aerosmith's Greatest Dimensions Pack"
B4: Carcinogen Crush | C4: AFI
B5: Almost Easy | C5: Avenged Sevenfold | D5: 39705 | E5: RB2 Export | F5: Export Has Expired
B6: Peace of Mind | C6: Boston | D6: 39532 | E6: DLC | F6: Part of "Boston Pack 01" and "Classic Rock Track Pack"
B7: Soothsayer | C7: Buckethead
B8: God Put a Smile upon Your Face | C8: Coldplay
B9: Violet Hill | C9: Coldplay
B10: Yellow | C10: Coldplay | D10: 40834 | E10: DLC | F10: Part of "Coldplay Collection 01"
B11: Nine Lives | C11: Def Leppard
B12: Photograph | C12: Def Leppard | D12: 40764 | E12: DLC | F12: Part of "Def Leppard Pack 01"
B13: Rock of Ages | C13: Def Leppard | D13: 40764 | E13: DLC | F13: Part of "Def Leppard Pack 01"
B14: Hole in the Earth | C14: Deftones | D14: 40337 | E14: DLC | F14: Part of "Deftones Pack 01"
B15: Ernten Was Wir Säen | C15: Die Fantastischen Vier
B16: Heroes of Our Time | C16: DragonForce
B17: Operation Ground and Pound | C17: DragonForce | D17: 40631 | E17: DLC | F17: DLC Single
B18: Revolution Deathsquad | C18: DragonForce
B19: Famous For Nothing | C19: Dropkick Murphys
B20: (F)lannigan's Ball | C20: Dropkick Murphys
B21: Johnny, I Hardly Knew Ya | C21: Dropkick Murphys
B22: So Payaso | C22: Extremoduro
B23: Tina | C23: Flyleaf
B24: All My Life | C24: Foo Fighters | D24: 40043 | E24: DLC | F24: Part of "Foo Fighters Pack 02"
B25: The Pretender | C25: Foo Fighters | D25: 40120 | E25: DLC | F25: Part of "Foo Fighters Pack 03"
B26: This Is a Call | C26: Foo Fighters | D26: 39805 | E26: DLC | F26: Part of "Foo Fighters Pack 01"
B27: Jukebox Hero | C27: Foreigner | D27: 39406 | E27: DLC | F27: Cover is a DLC Single
B28: The End Begins (to Rock) | C28: God of War II | I28: Guitar Hero III DLC
B29: Surfing with the Alien | C29: Joe Satriani | D29: 40099 | E29: DLC | F29: DLC Single | I29: Oct. 31, 2007- Sept. 12, 2008
B30: Any Way You Want It | C30: Journey | D30: 39705 | E30: RB2 | F30: Never Exportable From RB2
B31: I Predict a Riot | C31: Kaiser Chiefs | D31: 40043 | E31: DLC | F31: DLC Single
B32: Shoot the Runner | C32: Kasabian | D32: 39714 | E32: DLC | F32: DLC Single
B33: I Am Murloc | C33: L70ETC
B34: No More Sorrow | C34: Linkin Park
B35: Putting Holes in Happiness (Nick Zinner Remix) | C35: Marilyn Manson
B36: Sleeping Giant | C36: Mastodon
B37: All Nightmare Long | C37: Metallica
B38: Broken, Beat & Scarred | C38: Metallica
B39: Cyanide | C39: Metallica
B40: The Day That Never Comes | C40: Metallica
B41: The End of the Line | C41: Metallica
...

Sheet GH World Tour
B2: Song | C2: Artist | D2: Released Date | E2: Source | F2: Notes
B3: Beautiful Disaster | C3: 311 | D3: 41184 | E3: DLC | F3: Part of "311 Pack 01"
B4: The Kill | C4: 30 Seconds to Mars | D4: 39441 | E4: DLC | F4: DLC Single
B5: Too Much, Too Young, Too Fast | C5: Airbourne
B6: Ramblin' Man | C6: The Allman Brothers Band | D6: 39705 | E6: RB2 Export | F6: Export Has Expired
B7: Good God | C7: Anouk
B8: Never Too Late | C8: The Answer
B9: One Armed Scissor | C9: At the Drive-In | D9: 40477 | E9: RB3 Export | F9: Export Has Expired
B10: No Sleep Till Brooklyn | C10: Beastie Boys | D10: 40757 | E10: DLC | F10: DLC Single
B11: Hail to the Freaks | C11: Beatsteaks
B12: Rebel Yell | C12: Billy Idol | D12: 40050 | E12: DLC | F12: DLC Single
B13: Stillborn | C13: Black Label Society
B14: Weapon of Choice | C14: Black Rebel Motorcycle Club | D14: 39994 | E14: DLC | F14: DLC Single
B15: Dammit | C15: Blink-182 | D15: 39749 | E15: DLC | F15: DLC Single
B16: One Way or Another | C16: Blondie | D16: 39705 | E16: RB2 Export/DLC | F16: Export Has Expired, but re-released as a Single
B17: Hollywood Nights | C17: Bob Seger & The Silver Bullet Band
B18: Livin' on a Prayer | C18: Bon Jovi | D18: 39705 | E18: RB2 Export/DLC | F18: Export Has Expired but re-released as part of "Bon Jovi's Greatest Hit" Album
B19: Scream Aim Fire | C19: Bullet for My Valentine | D19: 41058 | E19: DLC | F19: Part of "Bullet For My Valentine Pack 01"
B20: Shiver | C20: Coldplay | D20: 44049 | E20: DLC | F20: Part of "Coldplay Parachutes to Everyday Life" Pack
B21: Up Around the Bend | C21: Creedence Clearwater Revival | D21: 40365 | E21: DLC | F21: Part of "Creedence Clearwater Revival Pack 01"
B22: Love Removal Machine | C22: The Cult
B23: Feel the Pain | C23: Dinosaur Jr. | D23: 39705 | E23: RB2 Export | F23: Export Has Expired
B24: Love Me Two Times | C24: The Doors | D24: 40477 | E24: DLC | F24: Part of "The Doors Greatest Hits" Album
B25: Pull Me Under | C25: Dream Theater | D25: 42894 | E25: DLC | F25: DLC Single
